Workbook

Sheet 157.5.6
A1: EXAMINING THE FEASIBILITY OF CONSUMPTION OF BUILT UP AREA
A2: CGO OFFICE COMPLEX
A4: A. PLOT, FSI & REGULATORY INPUTS (enter values for the plot being checked)
A5: Sr.No | B5: Particulars | C5: Details | D5: Units
A6: 1 | B6: Plot Number / Identification | C6: 157 5/6
A7: 2 | B7: Plot Area | C7: =CGO_PLOT_DIMENSIONS!C23 -> 4308.12 | D7: Sqm
A8: 3 | B8: Ground Coverage (footprint at ground level) | C8: 2483.1
A9: 4 | B9: Ground Coverage (Between heights 24m to 37.5m) | C9: 2080.23
A10: 5 | B10: Ground Coverage (Above the height of 37.5m) | C10: 1711.56 | D10: Sqm
A11: 6 | B11: Total Permissible FSI (Base + Additional) | C11: 4.8 | D11: —
A12: 7 | B12: Additional area for chowk, shaft, etc. | C12: 0.3 | D12: %
A13: 8 | B13: Front Setback | C13: 12 m
A14: 9 | B14: Side Setback | C14: 6 m
A15: 10 | B15: Max. Permissible Height of Building | C15: =CGO_PLOT_DIMENSIONS!I23 -> 73.2 | D15: m
A16: 11 | B16: Plinth Height | C16: 0.15 | D16: m
A17: 12 | B17: Typical Office Floor-to-Floor Height | C17: 3.3 | D17: m
A18: 13 | B18: Podium Parking Floor-to-Floor Height | C18: 2.4 | D18: m
A20: B. PERMISSIBLE BUA CALCULATION
A21: Sr.No | B21: Particulars | C21: Details | D21: Units
A22: 1 | B22: Total Permissible BUA (Plot Area x FSI) | C22: =C7*C11 -> 20678.976 | D22: Sqm
A23: 2 | B23: Additional area for chowk, shaft, etc. | C23: =C22*C12 -> 6203.6928 | D23: Sqm
A24: 3 | B24: Total BUA | C24: =C22+C23 -> 26882.669 | D24: Sqm
A26: C. BASEMENT CALCULATION
A27: Sr.No | B27: Particulars | C27: Details | D27: Units
A28: 1 | B28: Basement Setback from Plot Boundary (DCR 1991) | C28: 1.5 | D28: m
A29: 2 | B29: Basement Floor Plate Area (achievable footprint after 1.5 m margin) | C29: =CGO_PLOT_DIMENSIONS!H23 -> 3919.4 | D29: Sqm
A30: 3 | B30: No. of Basement Floors Proposed | C30: 3 | D30: Nos.
A31: 4 | B31: Basement Floor-to-Floor Height | C31: 3.3 | D31: m
A32: 5 | B32: Total Basement BUA (Floors x Floor Plate) | C32: =C30*C29 -> 11758.2 | D32: Sqm
A34: D. PARKING REQUIREMENTS
A35: Sr.No | B35: Particulars | C35: Value | D35: Units
A36: 1 | B36: Parking upto 1500 Sqm @ 37.5 Sqm per space | C36: =IF(C32<=1500, C32/37.5, 1500/37.5) -> 40 | D36: Nos.
A37: 2 | B37: Remaining Built up Area (BUA - 1500) | C37: =C24-1500 -> 25382.669 | D37: Sqm
A38: 3 | B38: Parking for remaining BUA @ 75 Sqm per space | C38: =IF(C24>1500, (C24-1500)/75, 0) -> 338.43558 | D38: Nos.
A39: 4 | B39: Total Parking Required | C39: =C36+C38 -> 378.43558 | D39: Nos.
A40: 5 | B40: Additional 10% Visitor Parking | C40: =C39*0.1 -> 37.843558 | D40: Nos.
A41: 6 | B41: Total Parking with Visitor | C41: =C39+C40 -> 416.27914 | D41: Nos.
A42: 7 | B42: BUA required for parking @ 35 Sqm per car | C42: =C41*35 -> 14569.77 | D42: Sqm
A43: 8 | B43: Parking requrement met in Basement | C43: =C32 -> 11758.2
A44: 9 | B44: Balance Parking area required | C44: =C42-C43 -> 2811.57 | D44: Sqm
...

Sheet 157.3.4
A1: EXAMINING THE FEASIBILITY OF CONSUMPTION OF BUILT UP AREA
A2: CGO OFFICE COMPLEX
A4: A. PLOT, FSI & REGULATORY INPUTS (enter values for the plot being checked)
A5: Sr.No | B5: Particulars | C5: Details | D5: Units
A6: 1 | B6: Plot Number / Identification | C6: 157 3/4
A7: 2 | B7: Plot Area | C7: =CGO_PLOT_DIMENSIONS!C22 -> 3785.56 | D7: Sqm
A8: 3 | B8: Ground Coverage (footprint at ground level) | C8: 2158.02
A9: 4 | B9: Ground Coverage (Between heights 24m to 37.5m) | C9: 1765.12
A10: 5 | B10: Ground Coverage (Above the height of 37.5m) | C10: 1408.21 | D10: Sqm
A11: 6 | B11: Total Permissible FSI (Base + Additional) | C11: 4.8 | D11: —
A12: 7 | B12: Additional area for chowk, shaft, etc. | C12: 0.3 | D12: %
A13: 8 | B13: Front Setback | C13: 12 m
A14: 9 | B14: Side Setback | C14: 6 m
A15: 10 | B15: Max. Permissible Height of Building | C15: =CGO_PLOT_DIMENSIONS!I22 -> 73.2 | D15: m
A16: 11 | B16: Plinth Height | C16: 0.15 | D16: m
A17: 12 | B17: Typical Office Floor-to-Floor Height | C17: 3.3 | D17: m
A18: 13 | B18: Podium Parking Floor-to-Floor Height | C18: 2.4 | D18: m
A20: B. PERMISSIBLE BUA CALCULATION
A21: Sr.No | B21: Particulars | C21: Details | D21: Units
A22: 1 | B22: Total Permissible BUA (Plot Area x FSI) | C22: =C7*C11 -> 18170.688 | D22: Sqm
A23: 2 | B23: Additional area for chowk, shaft, etc. | C23: =C22*C12 -> 5451.2064 | D23: Sqm
A24: 3 | B24: Total BUA | C24: =C22+C23 -> 23621.894 | D24: Sqm
A26: C. BASEMENT CALCULATION
A27: Sr.No | B27: Particulars | C27: Details | D27: Units
A28: 1 | B28: Basement Setback from Plot Boundary (DCR 1991) | C28: 1.5 | D28: m
A29: 2 | B29: Basement Floor Plate Area (achievable footprint after 1.5 m margin) | C29: =CGO_PLOT_DIMENSIONS!H22 -> 3425.39 | D29: Sqm
A30: 3 | B30: No. of Basement Floors Proposed | C30: 3 | D30: Nos.
A31: 4 | B31: Basement Floor-to-Floor Height | C31: 3.3 | D31: m
A32: 5 | B32: Total Basement BUA (Floors x Floor Plate) | C32: =C30*C29 -> 10276.17 | D32: Sqm
A34: D. PARKING REQUIREMENTS
A35: Sr.No | B35: Particulars | C35: Value | D35: Units
A36: 1 | B36: Parking upto 1500 Sqm @ 37.5 Sqm per space | C36: =IF(C32<=1500, C32/37.5, 1500/37.5) -> 40 | D36: Nos.
A37: 2 | B37: Remaining Built up Area (BUA - 1500) | C37: =C24-1500 -> 22121.894 | D37: Sqm
A38: 3 | B38: Parking for remaining BUA @ 75 Sqm per space | C38: =IF(C24>1500, (C24-1500)/75, 0) -> 294.95859 | D38: Nos.
A39: 4 | B39: Total Parking Required | C39: =C36+C38 -> 334.95859 | D39: Nos.
A40: 5 | B40: Additional 10% Visitor Parking | C40: =C39*0.1 -> 33.495859 | D40: Nos.
A41: 6 | B41: Total Parking with Visitor | C41: =C39+C40 -> 368.45445 | D41: Nos.
A42: 7 | B42: BUA required for parking @ 35 Sqm per car | C42: =C41*35 -> 12895.906 | D42: Sqm
A43: 8 | B43: Parking requrement met in Basement | C43: =C32 -> 10276.17
A44: 9 | B44: Balance Parking area required | C44: =C42-C43 -> 2619.7358 | D44: Sqm
...

Sheet 157.1.2
A1: EXAMINING THE FEASIBILITY OF CONSUMPTION OF BUILT UP AREA
A2: CGO OFFICE COMPLEX
A4: A. PLOT, FSI & REGULATORY INPUTS (enter values for the plot being checked)
A5: Sr.No | B5: Particulars | C5: Details | D5: Units
A6: 1 | B6: Plot Number / Identification | C6: 157 1/2
A7: 2 | B7: Plot Area | C7: 2104.16 | D7: Sqm
A8: 3 | B8: Ground Coverage (footprint at ground level) | C8: 965.49
A9: 4 | B9: Ground Coverage (Between heights 24m to 37.5m) | C9: 654.16
A10: 5 | B10: Ground Coverage (Above the height of 37.5m) | C10: 378.82 | D10: Sqm
A11: 6 | B11: Total Permissible FSI (Base + Additional) | C11: 4.8 | D11: —
A12: 7 | B12: Additional area for chowk, shaft, etc. | C12: 0.3 | D12: %
A13: 8 | B13: Front Setback | C13: 12 m
A14: 9 | B14: Side Setback | C14: 6 m
A15: 10 | B15: Max. Permissible Height of Building | C15: =CGO_PLOT_DIMENSIONS!I21 -> 73.2 | D15: m
A16: 11 | B16: Plinth Height | C16: 0.15 | D16: m
A17: 12 | B17: Typical Office Floor-to-Floor Height | C17: 3.3 | D17: m
A18: 13 | B18: Podium Parking Floor-to-Floor Height | C18: 2.4 | D18: m
A20: B. PERMISSIBLE BUA CALCULATION
A21: Sr.No | B21: Particulars | C21: Details | D21: Units
A22: 1 | B22: Total Permissible BUA (Plot Area x FSI) | C22: =C7*C11 -> 10099.968 | D22: Sqm
A23: 2 | B23: Additional area for chowk, shaft, etc. | C23: =C22*C12 -> 3029.9904 | D23: Sqm
A24: 3 | B24: Total BUA | C24: =C22+C23 -> 13129.958 | D24: Sqm
A26: C. BASEMENT CALCULATION
A27: Sr.No | B27: Particulars | C27: Details | D27: Units
A28: 1 | B28: Basement Setback from Plot Boundary (DCR 1991) | C28: 1.5 | D28: m
A29: 2 | B29: Basement Floor Plate Area (achievable footprint after 1.5 m margin) | C29: =CGO_PLOT_DIMENSIONS!H21 -> 1825.49 | D29: Sqm
A30: 3 | B30: No. of Basement Floors Proposed | C30: 3 | D30: Nos.
A31: 4 | B31: Basement Floor-to-Floor Height | C31: 3.3 | D31: m
A32: 5 | B32: Total Basement BUA (Floors x Floor Plate) | C32: =C30*C29 -> 5476.47 | D32: Sqm
A34: D. PARKING REQUIREMENTS
A35: Sr.No | B35: Particulars | C35: Value | D35: Units
A36: 1 | B36: Parking upto 1500 Sqm @ 37.5 Sqm per space | C36: =IF(C32<=1500, C32/37.5, 1500/37.5) -> 40 | D36: Nos.
A37: 2 | B37: Remaining Built up Area (BUA - 1500) | C37: =C24-1500 -> 11629.958 | D37: Sqm
A38: 3 | B38: Parking for remaining BUA @ 75 Sqm per space | C38: =IF(C24>1500, (C24-1500)/75, 0) -> 155.06611 | D38: Nos.
A39: 4 | B39: Total Parking Required | C39: =C36+C38 -> 195.06611 | D39: Nos.
A40: 5 | B40: Additional 10% Visitor Parking | C40: =C39*0.1 -> 19.506611 | D40: Nos.
A41: 6 | B41: Total Parking with Visitor | C41: =C39+C40 -> 214.57272 | D41: Nos.
A42: 7 | B42: BUA required for parking @ 35 Sqm per car | C42: =C41*35 -> 7510.0453 | D42: Sqm
A43: 8 | B43: Parking requrement met in Basement | C43: =C32 -> 5476.47
A44: 9 | B44: Balance Parking area required | C44: =C42-C43 -> 2033.5753 | D44: Sqm
...

Sheet 160.3.4
A1: EXAMINING THE FEASIBILITY OF CONSUMPTION OF BUILT UP AREA
A2: CGO OFFICE COMPLEX
A4: A. PLOT, FSI & REGULATORY INPUTS (enter values for the plot being checked)
A5: Sr.No | B5: Particulars | C5: Details | D5: Units
A6: 1 | B6: Plot Number / Identification | C6: 160 3/4
A7: 2 | B7: Plot Area | C7: 3169 | D7: Sqm
A8: 3 | B8: Ground Coverage (footprint at ground level) | C8: 1726.18
A9: 4 | B9: Ground Coverage (Between heights 24m to 37.5m) | C9: 1315.74
A10: 5 | B10: Ground Coverage (Above the height of 37.5m) | C10: 941.31 | D10: Sqm
A11: 6 | B11: Total Permissible FSI (Base + Additional) | C11: 10.1 | D11: —
A12: 7 | B12: Additional area for chowk, shaft, etc. | C12: 0.3 | D12: %
A13: 8 | B13: Front Setback | C13: 12 m
A14: 7 | B14: Side Setback | C14: 6 m
A15: 10 | B15: Max. Permissible Height of Building | C15: =CGO_PLOT_DIMENSIONS!I12 -> 153.72 | D15: m
A16: 11 | B16: Plinth Height | C16: 0.15 | D16: m
A17: 12 | B17: Typical Office Floor-to-Floor Height | C17: 3.3 | D17: m
A18: 13 | B18: Podium Parking Floor-to-Floor Height | C18: 2.4 | D18: m
A20: B. PERMISSIBLE BUA CALCULATION
A21: Sr.No | B21: Particulars | C21: Details | D21: Units
A22: 1 | B22: Total Permissible BUA (Plot Area x FSI) | C22: =C7*C11 -> 32006.9 | D22: Sqm
A23: 2 | B23: Additional area for chowk, shaft, etc. | C23: =C22*C12 -> 9602.07 | D23: Sqm
A24: 3 | B24: Total BUA | C24: =C22+C23 -> 41608.97 | D24: Sqm
A26: C. BASEMENT CALCULATION
A27: Sr.No | B27: Particulars | C27: Details | D27: Units
A28: 1 | B28: Basement Setback from Plot Boundary (DCR 1991) | C28: 1.5 | D28: m
A29: 2 | B29: Basement Floor Plate Area (achievable footprint after 1.5 m margin) | C29: =CGO_PLOT_DIMENSIONS!H12 -> 2827.54 | D29: Sqm
A30: 3 | B30: No. of Basement Floors Proposed | C30: 3 | D30: Nos.
A31: 4 | B31: Basement Floor-to-Floor Height | C31: 3.3 | D31: m
A32: 5 | B32: Total Basement BUA (Floors x Floor Plate) | C32: =C30*C29 -> 8482.62 | D32: Sqm
A34: D. PARKING REQUIREMENTS
A35: Sr.No | B35: Particulars | C35: Value | D35: Units
A36: 1 | B36: Parking upto 1500 Sqm @ 37.5 Sqm per space | C36: =IF(C32<=1500, C32/37.5, 1500/37.5) -> 40 | D36: Nos.
A37: 2 | B37: Remaining Built up Area (BUA - 1500) | C37: =C24-1500 -> 40108.97 | D37: Sqm
A38: 3 | B38: Parking for remaining BUA @ 75 Sqm per space | C38: =IF(C24>1500, (C24-1500)/75, 0) -> 534.78627 | D38: Nos.
A39: 4 | B39: Total Parking Required | C39: =C36+C38 -> 574.78627 | D39: Nos.
A40: 5 | B40: Additional 10% Visitor Parking | C40: =C39*0.1 -> 57.478627 | D40: Nos.
A41: 6 | B41: Total Parking with Visitor | C41: =C39+C40 -> 632.26489 | D41: Nos.
A42: 7 | B42: BUA required for parking @ 35 Sqm per car | C42: =C41*35 -> 22129.271 | D42: Sqm
A43: 8 | B43: Parking requrement met in Basement | C43: =C32 -> 8482.62
A44: 9 | B44: Balance Parking area required | C44: =C42-C43 -> 13646.651 | D44: Sqm
...

Sheet 160.1.2
A1: EXAMINING THE FEASIBILITY OF CONSUMPTION OF BUILT UP AREA
A2: CGO OFFICE COMPLEX
A4: A. PLOT, FSI & REGULATORY INPUTS (enter values for the plot being checked)
A5: Sr.No | B5: Particulars | C5: Details | D5: Units
A6: 1 | B6: Plot Number / Identification | C6: 160 1/2
A7: 2 | B7: Plot Area | C7: 3168.5 | D7: Sqm
A8: 3 | B8: Ground Coverage (footprint at ground level) | C8: 1725.79
A9: 4 | B9: Ground Coverage (Between heights 24m to 37.5m) | C9: 1315.32
A10: 5 | B10: Ground Coverage (Above the height of 37.5m) | C10: 940.86 | D10: Sqm
A11: 6 | B11: Total Permissible FSI (Base + Additional) | C11: 10.1 | D11: —
A12: 7 | B12: Additional area for chowk, shaft, etc. | C12: 0.3 | D12: %
A13: 8 | B13: Front Setback | C13: 12 m
A14: 9 | B14: Side Setback | C14: 6 m
A15: 10 | B15: Max. Permissible Height of Building | C15: =CGO_PLOT_DIMENSIONS!I11 -> 153.72 | D15: m
A16: 11 | B16: Plinth Height | C16: 0.15 | D16: m
A17: 12 | B17: Typical Office Floor-to-Floor Height | C17: 3.3 | D17: m
A18: 13 | B18: Podium Parking Floor-to-Floor Height | C18: 2.4 | D18: m
A20: B. PERMISSIBLE BUA CALCULATION
A21: Sr.No | B21: Particulars | C21: Details | D21: Units
A22: 1 | B22: Total Permissible BUA (Plot Area x FSI) | C22: =C7*C11 -> 32001.85 | D22: Sqm
A23: 2 | B23: Additional area for chowk, shaft, etc. | C23: =C22*C12 -> 9600.555 | D23: Sqm
A24: 3 | B24: Total BUA | C24: =C22+C23 -> 41602.405 | D24: Sqm
A26: C. BASEMENT CALCULATION
A27: Sr.No | B27: Particulars | C27: Details | D27: Units
A28: 1 | B28: Basement Setback from Plot Boundary (DCR 1991) | C28: 1.5 | D28: m
A29: 2 | B29: Basement Floor Plate Area (achievable footprint after 1.5 m margin) | C29: =CGO_PLOT_DIMENSIONS!H11 -> 2827.04 | D29: Sqm
A30: 3 | B30: No. of Basement Floors Proposed | C30: 3 | D30: Nos.
A31: 4 | B31: Basement Floor-to-Floor Height | C31: 3.3 | D31: m
A32: 5 | B32: Total Basement BUA (Floors x Floor Plate) | C32: =C30*C29 -> 8481.12 | D32: Sqm
A34: D. PARKING REQUIREMENTS
A35: Sr.No | B35: Particulars | C35: Value | D35: Units
A36: 1 | B36: Parking upto 1500 Sqm @ 37.5 Sqm per space | C36: =IF(C32<=1500, C32/37.5, 1500/37.5) -> 40 | D36: Nos.
A37: 2 | B37: Remaining Built up Area (BUA - 1500) | C37: =C24-1500 -> 40102.405 | D37: Sqm
A38: 3 | B38: Parking for remaining BUA @ 75 Sqm per space | C38: =IF(C24>1500, (C24-1500)/75, 0) -> 534.69873 | D38: Nos.
A39: 4 | B39: Total Parking Required | C39: =C36+C38 -> 574.69873 | D39: Nos.
A40: 5 | B40: Additional 10% Visitor Parking | C40: =C39*0.1 -> 57.469873 | D40: Nos.
A41: 6 | B41: Total Parking with Visitor | C41: =C39+C40 -> 632.16861 | D41: Nos.
A42: 7 | B42: BUA required for parking @ 35 Sqm per car | C42: =C41*35 -> 22125.901 | D42: Sqm
A43: 8 | B43: Parking requrement met in Basement | C43: =C32 -> 8481.12
A44: 9 | B44: Balance Parking area required | C44: =C42-C43 -> 13644.781 | D44: Sqm
...

Sheet 159.3.4
A1: EXAMINING THE FEASIBILITY OF CONSUMPTION OF BUILT UP AREA
A2: CGO OFFICE COMPLEX
A4: A. PLOT, FSI & REGULATORY INPUTS (enter values for the plot being checked)
A5: Sr.No | B5: Particulars | C5: Details | D5: Units
A6: 1 | B6: Plot Number / Identification | C6: 159 3/4
A7: 2 | B7: Plot Area | C7: 3172.69 | D7: Sqm
A8: 3 | B8: Ground Coverage (footprint at ground level) | C8: 1728.8
A9: 4 | B9: Ground Coverage (Between heights 24m to 37.5m) | C9: 1317.8
A10: 5 | B10: Ground Coverage (Above the height of 37.5m) | C10: 942.79 | D10: Sqm
A11: 6 | B11: Total Permissible FSI (Base + Additional) | C11: 4 | D11: —
A12: 7 | B12: Additional area for chowk, shaft, etc. | C12: 0.3 | D12: %
A13: 8 | B13: Front Setback | C13: 12 m
A14: 9 | B14: Side Setback | C14: 6 m
A15: 10 | B15: Max. Permissible Height of Building | C15: =CGO_PLOT_DIMENSIONS!I15 -> 87.84 | D15: m
A16: 11 | B16: Plinth Height | C16: 0.15 | D16: m
A17: 12 | B17: Typical Office Floor-to-Floor Height | C17: 3.3 | D17: m
A18: 13 | B18: Podium Parking Floor-to-Floor Height | C18: 2.4 | D18: m
A20: B. PERMISSIBLE BUA CALCULATION
A21: Sr.No | B21: Particulars | C21: Details | D21: Units
A22: 1 | B22: Total Permissible BUA (Plot Area x FSI) | C22: =C7*C11 -> 12690.76 | D22: Sqm
A23: 2 | B23: Additional area for chowk, shaft, etc. | C23: =C22*C12 -> 3807.228 | D23: Sqm
A24: 3 | B24: Total BUA | C24: =C22+C23 -> 16497.988 | D24: Sqm
A26: C. BASEMENT CALCULATION
A27: Sr.No | B27: Particulars | C27: Details | D27: Units
A28: 1 | B28: Basement Setback from Plot Boundary (DCR 1991) | C28: 1.5 | D28: m
A29: 2 | B29: Basement Floor Plate Area (achievable footprint after 1.5 m margin) | C29: =CGO_PLOT_DIMENSIONS!H15 -> 2830.95 | D29: Sqm
A30: 3 | B30: No. of Basement Floors Proposed | C30: 3 | D30: Nos.
A31: 4 | B31: Basement Floor-to-Floor Height | C31: 3.3 | D31: m
A32: 5 | B32: Total Basement BUA (Floors x Floor Plate) | C32: =C30*C29 -> 8492.85 | D32: Sqm
A34: D. PARKING REQUIREMENTS
A35: Sr.No | B35: Particulars | C35: Value | D35: Units
A36: 1 | B36: Parking upto 1500 Sqm @ 37.5 Sqm per space | C36: =IF(C32<=1500, C32/37.5, 1500/37.5) -> 40 | D36: Nos.
A37: 2 | B37: Remaining Built up Area (BUA - 1500) | C37: =C24-1500 -> 14997.988 | D37: Sqm
A38: 3 | B38: Parking for remaining BUA @ 75 Sqm per space | C38: =IF(C24>1500, (C24-1500)/75, 0) -> 199.97317 | D38: Nos.
A39: 4 | B39: Total Parking Required | C39: =C36+C38 -> 239.97317 | D39: Nos.
A40: 5 | B40: Additional 10% Visitor Parking | C40: =C39*0.1 -> 23.997317 | D40: Nos.
A41: 6 | B41: Total Parking with Visitor | C41: =C39+C40 -> 263.97049 | D41: Nos.
A42: 7 | B42: BUA required for parking @ 35 Sqm per car | C42: =C41*35 -> 9238.9672 | D42: Sqm
A43: 8 | B43: Parking requrement met in Basement | C43: =C32 -> 8492.85
A44: 9 | B44: Balance Parking area required | C44: =C42-C43 -> 746.11717 | D44: Sqm
...

Sheet 159.1.2
A1: EXAMINING THE FEASIBILITY OF CONSUMPTION OF BUILT UP AREA
A2: CGO OFFICE COMPLEX
A4: A. PLOT, FSI & REGULATORY INPUTS (enter values for the plot being checked)
A5: Sr.No | B5: Particulars | C5: Details | D5: Units
A6: 1 | B6: Plot Number / Identification | C6: 159 1/2
A7: 2 | B7: Plot Area | C7: 3171.66 | D7: Sqm
A8: 3 | B8: Ground Coverage (footprint at ground level) | C8: 1728.05
A9: 4 | B9: Ground Coverage (Between heights 24m to 37.5m) | C9: 1317.13
A10: 5 | B10: Ground Coverage (Above the height of 37.5m) | C10: 942.2 | D10: Sqm
A11: 6 | B11: Total Permissible FSI (Base + Additional) | C11: 4 | D11: —
A12: 7 | B12: Additional area for chowk, shaft, etc. | C12: 0.3 | D12: %
A13: 8 | B13: Front Setback | C13: 12 m
A14: 7 | B14: Side Setback | C14: 6 m
A15: 10 | B15: Max. Permissible Height of Building | C15: =CGO_PLOT_DIMENSIONS!I14 -> 87.84 | D15: m
A16: 11 | B16: Plinth Height | C16: 0.15 | D16: m
A17: 12 | B17: Typical Office Floor-to-Floor Height | C17: 3.3 | D17: m
A18: 13 | B18: Podium Parking Floor-to-Floor Height | C18: 2.4 | D18: m
A20: B. PERMISSIBLE BUA CALCULATION
A21: Sr.No | B21: Particulars | C21: Details | D21: Units
A22: 1 | B22: Total Permissible BUA (Plot Area x FSI) | C22: =C7*C11 -> 12686.64 | D22: Sqm
A23: 2 | B23: Additional area for chowk, shaft, etc. | C23: =C22*C12 -> 3805.992 | D23: Sqm
A24: 3 | B24: Total BUA | C24: =C22+C23 -> 16492.632 | D24: Sqm
A26: C. BASEMENT CALCULATION
A27: Sr.No | B27: Particulars | C27: Details | D27: Units
A28: 1 | B28: Basement Setback from Plot Boundary (DCR 1991) | C28: 1.5 | D28: m
A29: 2 | B29: Basement Floor Plate Area (achievable footprint after 1.5 m margin) | C29: =CGO_PLOT_DIMENSIONS!H14 -> 2829.98 | D29: Sqm
A30: 3 | B30: No. of Basement Floors Proposed | C30: 3 | D30: Nos.
A31: 4 | B31: Basement Floor-to-Floor Height | C31: 3.3 | D31: m
A32: 5 | B32: Total Basement BUA (Floors x Floor Plate) | C32: =C30*C29 -> 8489.94 | D32: Sqm
A34: D. PARKING REQUIREMENTS
A35: Sr.No | B35: Particulars | C35: Value | D35: Units
A36: 1 | B36: Parking upto 1500 Sqm @ 37.5 Sqm per space | C36: =IF(C32<=1500, C32/37.5, 1500/37.5) -> 40 | D36: Nos.
A37: 2 | B37: Remaining Built up Area (BUA - 1500) | C37: =C24-1500 -> 14992.632 | D37: Sqm
A38: 3 | B38: Parking for remaining BUA @ 75 Sqm per space | C38: =IF(C24>1500, (C24-1500)/75, 0) -> 199.90176 | D38: Nos.
A39: 4 | B39: Total Parking Required | C39: =C36+C38 -> 239.90176 | D39: Nos.
A40: 5 | B40: Additional 10% Visitor Parking | C40: =C39*0.1 -> 23.990176 | D40: Nos.
A41: 6 | B41: Total Parking with Visitor | C41: =C39+C40 -> 263.89194 | D41: Nos.
A42: 7 | B42: BUA required for parking @ 35 Sqm per car | C42: =C41*35 -> 9236.2178 | D42: Sqm
A43: 8 | B43: Parking requrement met in Basement | C43: =C32 -> 8489.94
A44: 9 | B44: Balance Parking area required | C44: =C42-C43 -> 746.27776 | D44: Sqm
...

Sheet 158.5.6
A1: EXAMINING THE FEASIBILITY OF CONSUMPTION OF BUILT UP AREA
A2: CGO OFFICE COMPLEX
A4: A. PLOT, FSI & REGULATORY INPUTS (enter values for the plot being checked)
A5: Sr.No | B5: Particulars | C5: Details | D5: Units
A6: 1 | B6: Plot Number / Identification | C6: =CGO_PLOT_DIMENSIONS!B19 -> 158 5/6
A7: 2 | B7: Plot Area | C7: =CGO_PLOT_DIMENSIONS!C19 -> 5093.99 | D7: Sqm
A8: 3 | B8: Ground Coverage (footprint at ground level) | C8: =CGO_PLOT_DIMENSIONS!D19 -> 3140.69
A9: 4 | B9: Ground Coverage (Between heights 24m to 37.5m) | C9: =CGO_PLOT_DIMENSIONS!E19 -> 2628.68
A10: 5 | B10: Ground Coverage (Above the height of 37.5m) | C10: =CGO_PLOT_DIMENSIONS!F19 -> 2150.87 | D10: Sqm
A11: 6 | B11: Total Permissible FSI (Base + Additional) | C11: 4.8 | D11: —
A12: 7 | B12: Additional area for chowk, shaft, etc. | C12: 0.3 | D12: %
A13: 8 | B13: Front Setback | C13: 12 m
A14: 7 | B14: Side Setback | C14: 6 m
A15: 10 | B15: Max. Permissible Height of Building | C15: 74 | D15: m
A16: 11 | B16: Plinth Height | C16: 0.15 | D16: m
A17: 12 | B17: Typical Office Floor-to-Floor Height | C17: 3.3 | D17: m
A18: 13 | B18: Podium Parking Floor-to-Floor Height | C18: 2.4 | D18: m
A20: B. PERMISSIBLE BUA CALCULATION
A21: Sr.No | B21: Particulars | C21: Details | D21: Units
A22: 1 | B22: Total Permissible BUA (Plot Area x FSI) | C22: =C7*C11 -> 24451.152 | D22: Sqm
A23: 2 | B23: Additional area for chowk, shaft, etc. | C23: =C22*C12 -> 7335.3456 | D23: Sqm
A24: 3 | B24: Total BUA | C24: =C22+C23 -> 31786.498 | D24: Sqm
A26: C. BASEMENT CALCULATION
A27: Sr.No | B27: Particulars | C27: Details | D27: Units
A28: 1 | B28: Basement Setback from Plot Boundary (DCR 1991) | C28: 1.5 | D28: m
A29: 2 | B29: Basement Floor Plate Area (achievable footprint after 1.5 m margin) | C29: =CGO_PLOT_DIMENSIONS!H19 -> 4661.95 | D29: Sqm
A30: 3 | B30: No. of Basement Floors Proposed | C30: 3 | D30: Nos.
A31: 4 | B31: Basement Floor-to-Floor Height | C31: 3.3 | D31: m
A32: 5 | B32: Total Basement BUA (Floors x Floor Plate) | C32: =C30*C29 -> 13985.85 | D32: Sqm
A34: D. PARKING REQUIREMENTS
A35: Sr.No | B35: Particulars | C35: Value | D35: Units
A36: 1 | B36: Parking upto 1500 Sqm @ 37.5 Sqm per space | C36: =IF(C32<=1500, C32/37.5, 1500/37.5) -> 40 | D36: Nos.
A37: 2 | B37: Remaining Built up Area (BUA - 1500) | C37: =C24-1500 -> 30286.498 | D37: Sqm
A38: 3 | B38: Parking for remaining BUA @ 75 Sqm per space | C38: =IF(C24>1500, (C24-1500)/75, 0) -> 403.81997 | D38: Nos.
A39: 4 | B39: Total Parking Required | C39: =C36+C38 -> 443.81997 | D39: Nos.
A40: 5 | B40: Additional 10% Visitor Parking | C40: =C39*0.1 -> 44.381997 | D40: Nos.
A41: 6 | B41: Total Parking with Visitor | C41: =C39+C40 -> 488.20196 | D41: Nos.
A42: 7 | B42: BUA required for parking @ 35 Sqm per car | C42: =C41*35 -> 17087.069 | D42: Sqm
A43: 8 | B43: Parking requrement met in Basement | C43: =C32 -> 13985.85
A44: 9 | B44: Balance Parking area required | C44: =C42-C43 -> 3101.2188 | D44: Sqm
...

Sheet 158.2.4
A1: EXAMINING THE FEASIBILITY OF CONSUMPTION OF BUILT UP AREA
A2: CGO OFFICE COMPLEX
A4: A. PLOT, FSI & REGULATORY INPUTS (enter values for the plot being checked)
A5: Sr.No | B5: Particulars | C5: Details | D5: Units
A6: 1 | B6: Plot Number / Identification | C6: 158 2/4
A7: 2 | B7: Plot Area | C7: =CGO_PLOT_DIMENSIONS!C18 -> 3507.4 | D7: Sqm
A8: 3 | B8: Ground Coverage (footprint at ground level) | C8: 1972.23
A9: 4 | B9: Ground Coverage (Between heights 24m to 37.5m) | C9: 1518.94
A10: 5 | B10: Ground Coverage (Above the height of 37.5m) | C10: 1101.65 | D10: Sqm
A11: 6 | B11: Total Permissible FSI (Base + Additional) | C11: 4.8 | D11: —
A12: 7 | B12: Additional area for chowk, shaft, etc. | C12: 0.3 | D12: %
A13: 8 | B13: Front Setback | C13: 12 m
A14: 7 | B14: Side Setback | C14: 6 m
A15: 10 | B15: Max. Permissible Height of Building | C15: =CGO_PLOT_DIMENSIONS!I18 -> 73.2 | D15: m
A16: 11 | B16: Plinth Height | C16: 0.15 | D16: m
A17: 12 | B17: Typical Office Floor-to-Floor Height | C17: 3.3 | D17: m
A18: 13 | B18: Podium Parking Floor-to-Floor Height | C18: 2.4 | D18: m
A20: B. PERMISSIBLE BUA CALCULATION
A21: Sr.No | B21: Particulars | C21: Details | D21: Units
A22: 1 | B22: Total Permissible BUA (Plot Area x FSI) | C22: =C7*C11 -> 16835.52 | D22: Sqm
A23: 2 | B23: Additional area for chowk, shaft, etc. | C23: =C22*C12 -> 5050.656 | D23: Sqm
A24: 3 | B24: Total BUA | C24: =C22+C23 -> 21886.176 | D24: Sqm
A26: C. BASEMENT CALCULATION
A27: Sr.No | B27: Particulars | C27: Details | D27: Units
A28: 1 | B28: Basement Setback from Plot Boundary (DCR 1991) | C28: 1.5 | D28: m
A29: 2 | B29: Basement Floor Plate Area (achievable footprint after 1.5 m margin) | C29: =CGO_PLOT_DIMENSIONS!H18 -> 3143.59 | D29: Sqm
A30: 3 | B30: No. of Basement Floors Proposed | C30: 3 | D30: Nos.
A31: 4 | B31: Basement Floor-to-Floor Height | C31: 3.3 | D31: m
A32: 5 | B32: Total Basement BUA (Floors x Floor Plate) | C32: =C30*C29 -> 9430.77 | D32: Sqm
A34: D. PARKING REQUIREMENTS
A35: Sr.No | B35: Particulars | C35: Value | D35: Units
A36: 1 | B36: Parking upto 1500 Sqm @ 37.5 Sqm per space | C36: =IF(C32<=1500, C32/37.5, 1500/37.5) -> 40 | D36: Nos.
A37: 2 | B37: Remaining Built up Area (BUA - 1500) | C37: =C24-1500 -> 20386.176 | D37: Sqm
A38: 3 | B38: Parking for remaining BUA @ 75 Sqm per space | C38: =IF(C24>1500, (C24-1500)/75, 0) -> 271.81568 | D38: Nos.
A39: 4 | B39: Total Parking Required | C39: =C36+C38 -> 311.81568 | D39: Nos.
A40: 5 | B40: Additional 10% Visitor Parking | C40: =C39*0.1 -> 31.181568 | D40: Nos.
A41: 6 | B41: Total Parking with Visitor | C41: =C39+C40 -> 342.99725 | D41: Nos.
A42: 7 | B42: BUA required for parking @ 35 Sqm per car | C42: =C41*35 -> 12004.904 | D42: Sqm
A43: 8 | B43: Parking requrement met in Basement | C43: =C32 -> 9430.77
A44: 9 | B44: Balance Parking area required | C44: =C42-C43 -> 2574.1337 | D44: Sqm
...

Sheet 158.1.3
A1: EXAMINING THE FEASIBILITY OF CONSUMPTION OF BUILT UP AREA
A2: CGO OFFICE COMPLEX
A4: A. PLOT, FSI & REGULATORY INPUTS (enter values for the plot being checked)
A5: Sr.No | B5: Particulars | C5: Details | D5: Units
A6: 1 | B6: Plot Number / Identification | C6: 158 1/3
A7: 2 | B7: Plot Area | C7: 3508.84 | D7: Sqm
A8: 3 | B8: Ground Coverage (footprint at ground level) | C8: 1973.43
A9: 4 | B9: Ground Coverage (Between heights 24m to 37.5m) | C9: 1520.09
A10: 5 | B10: Ground Coverage (Above the height of 37.5m) | C10: 1102.76 | D10: Sqm
A11: 6 | B11: Total Permissible FSI (Base + Additional) | C11: 4.8 | D11: —
A12: 7 | B12: Additional area for chowk, shaft, etc. | C12: 0.3 | D12: %
A13: 8 | B13: Front Setback | C13: 12 m
A14: 7 | B14: Side Setback | C14: 6 m
A15: 10 | B15: Max. Permissible Height of Building | C15: =CGO_PLOT_DIMENSIONS!I17 -> 73.2 | D15: m
A16: 11 | B16: Plinth Height | C16: 0.15 | D16: m
A17: 12 | B17: Typical Office Floor-to-Floor Height | C17: 3.3 | D17: m
A18: 13 | B18: Podium Parking Floor-to-Floor Height | C18: 2.4 | D18: m
A20: B. PERMISSIBLE BUA CALCULATION
A21: Sr.No | B21: Particulars | C21: Details | D21: Units
A22: 1 | B22: Total Permissible BUA (Plot Area x FSI) | C22: =C7*C11 -> 16842.432 | D22: Sqm
A23: 2 | B23: Additional area for chowk, shaft, etc. | C23: =C22*C12 -> 5052.7296 | D23: Sqm
A24: 3 | B24: Total BUA | C24: =C22+C23 -> 21895.162 | D24: Sqm
A26: C. BASEMENT CALCULATION
A27: Sr.No | B27: Particulars | C27: Details | D27: Units
A28: 1 | B28: Basement Setback from Plot Boundary (DCR 1991) | C28: 1.5 | D28: m
A29: 2 | B29: Basement Floor Plate Area (achievable footprint after 1.5 m margin) | C29: =CGO_PLOT_DIMENSIONS!H17 -> 3145.08 | D29: Sqm
A30: 3 | B30: No. of Basement Floors Proposed | C30: 3 | D30: Nos.
A31: 4 | B31: Basement Floor-to-Floor Height | C31: 3.3 | D31: m
A32: 5 | B32: Total Basement BUA (Floors x Floor Plate) | C32: =C30*C29 -> 9435.24 | D32: Sqm
A34: D. PARKING REQUIREMENTS
A35: Sr.No | B35: Particulars | C35: Value | D35: Units
A36: 1 | B36: Parking upto 1500 Sqm @ 37.5 Sqm per space | C36: =IF(C32<=1500, C32/37.5, 1500/37.5) -> 40 | D36: Nos.
A37: 2 | B37: Remaining Built up Area (BUA - 1500) | C37: =C24-1500 -> 20395.162 | D37: Sqm
A38: 3 | B38: Parking for remaining BUA @ 75 Sqm per space | C38: =IF(C24>1500, (C24-1500)/75, 0) -> 271.93549 | D38: Nos.
A39: 4 | B39: Total Parking Required | C39: =C36+C38 -> 311.93549 | D39: Nos.
A40: 5 | B40: Additional 10% Visitor Parking | C40: =C39*0.1 -> 31.193549 | D40: Nos.
A41: 6 | B41: Total Parking with Visitor | C41: =C39+C40 -> 343.12904 | D41: Nos.
A42: 7 | B42: BUA required for parking @ 35 Sqm per car | C42: =C41*35 -> 12009.516 | D42: Sqm
A43: 8 | B43: Parking requrement met in Basement | C43: =C32 -> 9435.24
A44: 9 | B44: Balance Parking area required | C44: =C42-C43 -> 2574.2763 | D44: Sqm
...

Sheet 146.3.4
A1: EXAMINING THE FEASIBILITY OF CONSUMPTION OF BUILT UP AREA
A2: CGO OFFICE COMPLEX
A4: A. PLOT, FSI & REGULATORY INPUTS (enter values for the plot being checked)
A5: Sr.No | B5: Particulars | C5: Details | D5: Units
A6: 1 | B6: Plot Number / Identification | C6: 146 3/4
A7: 2 | B7: Plot Area | C7: 3167.73 | D7: Sqm
A8: 3 | B8: Ground Coverage (footprint at ground level) | C8: 1725.87
A9: 4 | B9: Ground Coverage (Between heights 24m to 37.5m) | C9: 1315.39
A10: 5 | B10: Ground Coverage (Above the height of 37.5m) | C10: 940.54 | D10: Sqm
A11: 6 | B11: Total Permissible FSI (Base + Additional) | C11: =CGO_PLOT_DIMENSIONS!G9 -> 10.8 | D11: —
A12: 7 | B12: Additional area for chowk, shaft, etc. | C12: 0.3 | D12: %
A13: 8 | B13: Front Setback | C13: 12 m
A14: 7 | B14: Side Setback | C14: 6 m
A15: 10 | B15: Max. Permissible Height of Building | C15: =CGO_PLOT_DIMENSIONS!I9 -> 164.7 | D15: m
A16: 11 | B16: Plinth Height | C16: 0.15 | D16: m
A17: 12 | B17: Typical Office Floor-to-Floor Height | C17: 3.3 | D17: m
A18: 13 | B18: Podium Parking Floor-to-Floor Height | C18: 2.4 | D18: m
A20: B. PERMISSIBLE BUA CALCULATION
A21: Sr.No | B21: Particulars | C21: Details | D21: Units
A22: 1 | B22: Total Permissible BUA (Plot Area x FSI) | C22: =C7*C11 -> 34211.484 | D22: Sqm
A23: 2 | B23: Additional area for chowk, shaft, etc. | C23: =C22*C12 -> 10263.445 | D23: Sqm
A24: 3 | B24: Total BUA | C24: =C22+C23 -> 44474.929 | D24: Sqm
A26: C. BASEMENT CALCULATION
A27: Sr.No | B27: Particulars | C27: Details | D27: Units
A28: 1 | B28: Basement Setback from Plot Boundary (DCR 1991) | C28: 1.5 | D28: m
A29: 2 | B29: Basement Floor Plate Area (achievable footprint after 1.5 m margin) | C29: =CGO_PLOT_DIMENSIONS!H9 -> 2826.33 | D29: Sqm
A30: 3 | B30: No. of Basement Floors Proposed | C30: 3 | D30: Nos.
A31: 4 | B31: Basement Floor-to-Floor Height | C31: 3.3 | D31: m
A32: 5 | B32: Total Basement BUA (Floors x Floor Plate) | C32: =C30*C29 -> 8478.99 | D32: Sqm
A34: D. PARKING REQUIREMENTS
A35: Sr.No | B35: Particulars | C35: Value | D35: Units
A36: 1 | B36: Parking upto 1500 Sqm @ 37.5 Sqm per space | C36: =IF(C32<=1500, C32/37.5, 1500/37.5) -> 40 | D36: Nos.
A37: 2 | B37: Remaining Built up Area (BUA - 1500) | C37: =C24-1500 -> 42974.929 | D37: Sqm
A38: 3 | B38: Parking for remaining BUA @ 75 Sqm per space | C38: =IF(C24>1500, (C24-1500)/75, 0) -> 572.99906 | D38: Nos.
A39: 4 | B39: Total Parking Required | C39: =C36+C38 -> 612.99906 | D39: Nos.
A40: 5 | B40: Additional 10% Visitor Parking | C40: =C39*0.1 -> 61.299906 | D40: Nos.
A41: 6 | B41: Total Parking with Visitor | C41: =C39+C40 -> 674.29896 | D41: Nos.
A42: 7 | B42: BUA required for parking @ 35 Sqm per car | C42: =C41*35 -> 23600.464 | D42: Sqm
A43: 8 | B43: Parking requrement met in Basement | C43: =C32 -> 8478.99
A44: 9 | B44: Balance Parking area required | C44: =C42-C43 -> 15121.474 | D44: Sqm
...

Sheet 146.1.2
A1: EXAMINING THE FEASIBILITY OF CONSUMPTION OF BUILT UP AREA
A2: CGO OFFICE COMPLEX
A4: A. PLOT, FSI & REGULATORY INPUTS (enter values for the plot being checked)
A5: Sr.No | B5: Particulars | C5: Details | D5: Units
A6: 1 | B6: Plot Number / Identification | C6: 146 1/2
A7: 2 | B7: Plot Area | C7: 3167.22 | D7: Sqm
A8: 3 | B8: Ground Coverage (footprint at ground level) | C8: 1724.52
A9: 4 | B9: Ground Coverage (Between heights 24m to 37.5m) | C9: 1314.31
A10: 5 | B10: Ground Coverage (Above the height of 37.5m) | C10: 940.3 | D10: Sqm
A11: 6 | B11: Total Permissible FSI (Base + Additional) | C11: =CGO_PLOT_DIMENSIONS!G8 -> 10.8 | D11: —
A12: 7 | B12: Additional area for chowk, shaft, etc. | C12: 0.3 | D12: %
A13: 8 | B13: Front Setback | C13: 12 m
A14: 7 | B14: Side Setback | C14: 6 m
A15: 10 | B15: Max. Permissible Height of Building | C15: =CGO_PLOT_DIMENSIONS!I8 -> 164.7 | D15: m
A16: 11 | B16: Plinth Height | C16: 0.15 | D16: m
A17: 12 | B17: Typical Office Floor-to-Floor Height | C17: 3.3 | D17: m
A18: 13 | B18: Podium Parking Floor-to-Floor Height | C18: 2.4 | D18: m
A20: B. PERMISSIBLE BUA CALCULATION
A21: Sr.No | B21: Particulars | C21: Details | D21: Units
A22: 1 | B22: Total Permissible BUA (Plot Area x FSI) | C22: =C7*C11 -> 34205.976 | D22: Sqm
A23: 2 | B23: Additional area for chowk, shaft, etc. | C23: =C22*C12 -> 10261.793 | D23: Sqm
A24: 3 | B24: Total BUA | C24: =C22+C23 -> 44467.769 | D24: Sqm
A26: C. BASEMENT CALCULATION
A27: Sr.No | B27: Particulars | C27: Details | D27: Units
A28: 1 | B28: Basement Setback from Plot Boundary (DCR 1991) | C28: 1.5 | D28: m
A29: 2 | B29: Basement Floor Plate Area (achievable footprint after 1.5 m margin) | C29: =CGO_PLOT_DIMENSIONS!H8 -> 2825.86 | D29: Sqm
A30: 3 | B30: No. of Basement Floors Proposed | C30: 3 | D30: Nos.
A31: 4 | B31: Basement Floor-to-Floor Height | C31: 3.3 | D31: m
A32: 5 | B32: Total Basement BUA (Floors x Floor Plate) | C32: =C30*C29 -> 8477.58 | D32: Sqm
A34: D. PARKING REQUIREMENTS
A35: Sr.No | B35: Particulars | C35: Value | D35: Units
A36: 1 | B36: Parking upto 1500 Sqm @ 37.5 Sqm per space | C36: =IF(C32<=1500, C32/37.5, 1500/37.5) -> 40 | D36: Nos.
A37: 2 | B37: Remaining Built up Area (BUA - 1500) | C37: =C24-1500 -> 42967.769 | D37: Sqm
A38: 3 | B38: Parking for remaining BUA @ 75 Sqm per space | C38: =IF(C24>1500, (C24-1500)/75, 0) -> 572.90358 | D38: Nos.
A39: 4 | B39: Total Parking Required | C39: =C36+C38 -> 612.90358 | D39: Nos.
A40: 5 | B40: Additional 10% Visitor Parking | C40: =C39*0.1 -> 61.290358 | D40: Nos.
A41: 6 | B41: Total Parking with Visitor | C41: =C39+C40 -> 674.19394 | D41: Nos.
A42: 7 | B42: BUA required for parking @ 35 Sqm per car | C42: =C41*35 -> 23596.788 | D42: Sqm
A43: 8 | B43: Parking requrement met in Basement | C43: =C32 -> 8477.58
A44: 9 | B44: Balance Parking area required | C44: =C42-C43 -> 15119.208 | D44: Sqm
...

Sheet 145.3.4
A1: EXAMINING THE FEASIBILITY OF CONSUMPTION OF BUILT UP AREA
A2: CGO OFFICE COMPLEX
A4: A. PLOT, FSI & REGULATORY INPUTS (enter values for the plot being checked)
A5: Sr.No | B5: Particulars | C5: Details | D5: Units
A6: 1 | B6: Plot Number / Identification | C6: =CGO_PLOT_DIMENSIONS!B6 -> 145 3/4
A7: 2 | B7: Plot Area | C7: =CGO_PLOT_DIMENSIONS!C6 -> 3167.85 | D7: Sqm
A8: 3 | B8: Ground Coverage (footprint at ground level) | C8: =CGO_PLOT_DIMENSIONS!D6 -> 1725.34
A9: 4 | B9: Ground Coverage (Between heights 24m to 37.5m) | C9: =CGO_PLOT_DIMENSIONS!E6 -> 1314.98
A10: 5 | B10: Ground Coverage (Above the height of 37.5m) | C10: =CGO_PLOT_DIMENSIONS!F6 -> 940.62 | D10: Sqm
A11: 6 | B11: Total Permissible FSI (Base + Additional) | C11: =CGO_PLOT_DIMENSIONS!G6 -> 10.8 | D11: —
A12: 7 | B12: Additional area for chowk, shaft, etc. | C12: 0.3 | D12: %
A13: 8 | B13: Front Setback | C13: 12 m
A14: 7 | B14: Side Setback | C14: 6 m
A15: 10 | B15: Max. Permissible Height of Building | C15: =CGO_PLOT_DIMENSIONS!I6 -> 164.7 | D15: m
A16: 11 | B16: Plinth Height | C16: 0.15 | D16: m
A17: 12 | B17: Typical Office Floor-to-Floor Height | C17: 3.3 | D17: m
A18: 13 | B18: Podium Parking Floor-to-Floor Height | C18: 2.4 | D18: m
A20: B. PERMISSIBLE BUA CALCULATION
A21: Sr.No | B21: Particulars | C21: Details | D21: Units
A22: 1 | B22: Total Permissible BUA (Plot Area x FSI) | C22: =C7*C11 -> 34212.78 | D22: Sqm
A23: 2 | B23: Additional area for chowk, shaft, etc. | C23: =C22*C12 -> 10263.834 | D23: Sqm
A24: 3 | B24: Total BUA | C24: =C22+C23 -> 44476.614 | D24: Sqm
A26: C. BASEMENT CALCULATION
A27: Sr.No | B27: Particulars | C27: Details | D27: Units
A28: 1 | B28: Basement Setback from Plot Boundary (DCR 1991) | C28: 1.5 | D28: m
A29: 2 | B29: Basement Floor Plate Area (achievable footprint after 1.5 m margin) | C29: =CGO_PLOT_DIMENSIONS!H6 -> 2826.44 | D29: Sqm
A30: 3 | B30: No. of Basement Floors Proposed | C30: 3 | D30: Nos.
A31: 4 | B31: Basement Floor-to-Floor Height | C31: 3.3 | D31: m
A32: 5 | B32: Total Basement BUA (Floors x Floor Plate) | C32: =C30*C29 -> 8479.32 | D32: Sqm
A34: D. PARKING REQUIREMENTS
A35: Sr.No | B35: Particulars | C35: Value | D35: Units
A36: 1 | B36: Parking upto 1500 Sqm @ 37.5 Sqm per space | C36: =IF(C32<=1500, C32/37.5, 1500/37.5) -> 40 | D36: Nos.
A37: 2 | B37: Remaining Built up Area (BUA - 1500) | C37: =C24-1500 -> 42976.614 | D37: Sqm
A38: 3 | B38: Parking for remaining BUA @ 75 Sqm per space | C38: =IF(C24>1500, (C24-1500)/75, 0) -> 573.02152 | D38: Nos.
A39: 4 | B39: Total Parking Required | C39: =C36+C38 -> 613.02152 | D39: Nos.
A40: 5 | B40: Additional 10% Visitor Parking | C40: =C39*0.1 -> 61.302152 | D40: Nos.
A41: 6 | B41: Total Parking with Visitor | C41: =C39+C40 -> 674.32367 | D41: Nos.
A42: 7 | B42: BUA required for parking @ 35 Sqm per car | C42: =C41*35 -> 23601.329 | D42: Sqm
A43: 8 | B43: Parking requrement met in Basement | C43: =C32 -> 8479.32
A44: 9 | B44: Balance Parking area required | C44: =C42-C43 -> 15122.009 | D44: Sqm
...

Sheet 145.1.2
A1: EXAMINING THE FEASIBILITY OF CONSUMPTION OF BUILT UP AREA
A2: CGO OFFICE COMPLEX
A4: A. PLOT, FSI & REGULATORY INPUTS (enter values for the plot being checked)
A5: Sr.No | B5: Particulars | C5: Details | D5: Units
A6: 1 | B6: Plot Number / Identification | C6: =CGO_PLOT_DIMENSIONS!B5 -> 145 1/2
A7: 2 | B7: Plot Area | C7: =CGO_PLOT_DIMENSIONS!C5 -> 3167.09 | D7: Sqm
A8: 3 | B8: Ground Coverage (footprint at ground level) | C8: =CGO_PLOT_DIMENSIONS!D5 -> 1724.47
A9: 4 | B9: Ground Coverage (Between heights 24m to 37.5m) | C9: =CGO_PLOT_DIMENSIONS!E5 -> 1314.53
A10: 5 | B10: Ground Coverage (Above the height of 37.5m) | C10: =CGO_PLOT_DIMENSIONS!F6 -> 940.62 | D10: Sqm
A11: 6 | B11: Total Permissible FSI (Base + Additional) | C11: 10.8 | D11: —
A12: 7 | B12: Additional area for chowk, shaft, etc. | C12: 0.3 | D12: %
A13: 8 | B13: Front Setback | C13: 12 m
A14: 7 | B14: Side Setback | C14: 6 m
A15: 10 | B15: Max. Permissible Height of Building | C15: 164.7 | D15: m
A16: 11 | B16: Plinth Height | C16: 0.15 | D16: m
A17: 12 | B17: Typical Office Floor-to-Floor Height | C17: 3.3 | D17: m
A18: 13 | B18: Podium Parking Floor-to-Floor Height | C18: 2.4 | D18: m
A20: B. PERMISSIBLE BUA CALCULATION
A21: Sr.No | B21: Particulars | C21: Details | D21: Units
A22: 1 | B22: Total Permissible BUA (Plot Area x FSI) | C22: =C7*C11 -> 34204.572 | D22: Sqm
A23: 2 | B23: Additional area for chowk, shaft, etc. | C23: =C22*C12 -> 10261.372 | D23: Sqm
A24: 3 | B24: Total BUA | C24: =C22+C23 -> 44465.944 | D24: Sqm
A26: C. BASEMENT CALCULATION
A27: Sr.No | B27: Particulars | C27: Details | D27: Units
A28: 1 | B28: Basement Setback from Plot Boundary (DCR 1991) | C28: 1.5 | D28: m
A29: 2 | B29: Basement Floor Plate Area (achievable footprint after 1.5 m margin) | C29: =CGO_PLOT_DIMENSIONS!H5 -> 2825.34 | D29: Sqm
A30: 3 | B30: No. of Basement Floors Proposed | C30: 3 | D30: Nos.
A31: 4 | B31: Basement Floor-to-Floor Height | C31: 3.3 | D31: m
A32: 5 | B32: Total Basement BUA (Floors x Floor Plate) | C32: =C30*C29 -> 8476.02 | D32: Sqm
A34: D. PARKING REQUIREMENTS
A35: Sr.No | B35: Particulars | C35: Value | D35: Units
A36: 1 | B36: Parking upto 1500 Sqm @ 37.5 Sqm per space | C36: =IF(C32<=1500, C32/37.5, 1500/37.5) -> 40 | D36: Nos.
A37: 2 | B37: Remaining Built up Area (BUA - 1500) | C37: =C24-1500 -> 42965.944 | D37: Sqm
A38: 3 | B38: Parking for remaining BUA @ 75 Sqm per space | C38: =IF(C24>1500, (C24-1500)/75, 0) -> 572.87925 | D38: Nos.
A39: 4 | B39: Total Parking Required | C39: =C36+C38 -> 612.87925 | D39: Nos.
A40: 5 | B40: Additional 10% Visitor Parking | C40: =C39*0.1 -> 61.287925 | D40: Nos.
A41: 6 | B41: Total Parking with Visitor | C41: =C39+C40 -> 674.16717 | D41: Nos.
A42: 7 | B42: BUA required for parking @ 35 Sqm per car | C42: =C41*35 -> 23595.851 | D42: Sqm
A43: 8 | B43: Parking requrement met in Basement | C43: =C32 -> 8476.02
A44: 9 | B44: Balance Parking area required | C44: =C42-C43 -> 15119.831 | D44: Sqm
...

Sheet CGO_PLOT_DIMENSIONS
A1: CGO COMPLEX – PLOT DIMENSIONS & GC AREA SUMMARY
A2: Setback Scenarios: 12M Front + 6M Side | 12M Front + 9M Side | 12M All Sides
A3: Plot | B3: Sub-Plot | C3: Area (SQM) | D3: GC Area – 12M Front + 6M Side (SQM) | E3: GC Area – 12M Front + 9M Side (SQM) | F3: GC Area – 12M All Sides (SQM) | G3: FSI | H3: BASEMENT FLOOR PLATE AREA WITH 1.5M SETBACK (SQM) | I3: MAX.HEIGHT
A4: PLOT 145 (Inc. 1/2/3/4) | B4: TOTAL | C4: 6334.49
B5: 145 1/2 | C5: 3167.09 | D5: 1724.47 | E5: 1314.53 | F5: 940.1 | G5: 10.8 | H5: 2825.34 | I5: 164.7
B6: 145 3/4 | C6: 3167.85 | D6: 1725.34 | E6: 1314.98 | F6: 940.62 | G6: 10.8 | H6: 2826.44 | I6: 164.7
A7: PLOT 146 (Inc. 1/2/3/4) | B7: TOTAL | C7: 6334.49
B8: 146 1/2 | C8: 3167.22 | D8: 1724.52 | E8: 1314.31 | F8: 940.3 | G8: 10.8 | H8: 2825.86 | I8: 164.7
B9: 146 3/4 | C9: 3167.73 | D9: 1725.87 | E9: 1315.39 | F9: 940.54 | G9: 10.8 | H9: 2826.33 | I9: 164.7
A10: PLOT 160 (Inc. 1/2/3/4) | B10: TOTAL | C10: 6333.57
B11: 160 1/2 | C11: 3168.5 | D11: 1725.79 | E11: 1315.32 | F11: 940.86 | G11: 10.1 | H11: 2827.04 | I11: 153.72
B12: 160 3/4 | C12: 3169 | D12: 1726.18 | E12: 1315.74 | F12: 941.31 | G12: 10.1 | H12: 2827.54 | I12: 153.72
A13: PLOT 159 (Inc. 1/2/3/4) | B13: TOTAL | C13: 6334.84
B14: 159 1/2 | C14: 3171.66 | D14: 1728.05 | E14: 1317.13 | F14: 942.2 | G14: 4 | H14: 2829.98 | I14: 87.84
B15: 159 3/4 | C15: 3172.69 | D15: 1728.8 | E15: 1317.8 | F15: 942.79 | G15: 4 | H15: 2830.95 | I15: 87.84
A16: PLOT 158 (Inc. 1/2/3/4/5/6) | B16: TOTAL | C16: 12111.56
B17: 158 1/3 | C17: 3508.84 | D17: 1973.43 | E17: 1520.09 | F17: 1102.76 | G17: 4.8 | H17: 3145.08 | I17: 73.2
B18: 158 2/4 | C18: 3507.4 | D18: 1972.23 | E18: 1518.94 | F18: 1101.65 | G18: 4.8 | H18: 3143.59 | I18: 73.2
B19: 158 5/6 | C19: 5093.99 | D19: 3140.69 | E19: 2628.68 | F19: 2150.87 | G19: 4.8 | H19: 4661.95 | I19: 73.2
A20: PLOT 157 (Inc. 1/2/3/4/5/6) | B20: TOTAL | C20: 10197.5
B21: 157 1/2 | C21: 2104.16 | D21: 965.49 | E21: 654.16 | F21: 378.82 | G21: 4.8 | H21: 1825.49 | I21: 73.2
B22: 157 3/4 | C22: 3785.56 | D22: 2158.02 | E22: 1765.12 | F22: 1408.21 | G22: 4.8 | H22: 3425.39 | I22: 73.2
B23: 157 5/6 | C23: 4308.12 | D23: 2483.1 | E23: 2080.23 | F23: 1711.56 | G23: 4.8 | H23: 3919.4 | I23: 73.2
A25: LEGEND
A26: A – Plot identifier (combined area)
A27: B – Total row for the plot group
A28: C – GC Area with 12M Front + 6M Side setbacks
A29: D – GC Area with 12M Front + 9M Side setbacks
A30: E – GC Area with 12M setback on all sides
A32: Source: CGO_COMPLEX_PLOT_DIMENSIONS.dxf | Data extracted directly from AutoCAD DXF entities | All areas in Square Metres (SQM)
